Workbook

Sheet Overview
E7: Testcase
E10: MBFS - Ứng dụng di động
C14: Project Name: | E14: MBFS - Ứng dụng di động | I14: Reviewer: | K14: Tien.nguyen2
C15: Document Code: | E15: MBFS - Ứng dụng di động | I15: Role: | K15: QC Leader
C16: Platform | I16: Reviewed Date:
C17: Created By: | E17: Trang.bui3 | I17: Approver: | K17: Chung.vu
C18: Role: | E18: QC | I18: Role: | K18: PM
C19: Created Date: | E19: 46153 | I19: Approved Date:
C20: Version | E20: 0.1

Sheet Test Plan&report
B1: TEST REPORT
B2: Function ID | C2: Test coverage | D2: Test success coverage | E2: Total TCs | F2: Pass | G2: Fail | H2: Pending | I2: N/A | J2: Untested
B3: FUNC01 | C3: =IFERROR((F3+G3)/(E3-H3-I3),0) -> 0 | D3: =IFERROR((F3)/(E3-H3-I3),0) -> 0 | E3: =SUM(F3:J3) -> #REF! | F3: ='Tên tính năng'!J1+'Tên tính năng'!M1 -> #REF! | G3: ='Tên tính năng'!J2+'Tên tính năng'!M2 -> #REF! | H3: ='Tên tính năng'!J5+'Tên tính năng'!M5 -> #REF! | I3: ='Tên tính năng'!J4+'Tên tính năng'!M4 -> #REF! | J3: ='Tên tính năng'!J3+'Tên tính năng'!M3 -> #REF!
B9: Total | C9: =IFERROR((F9+G9)/(E9-H9-I9),0) -> 0 | D9: =IFERROR((F9)/(E9-H9-I9),0) -> 0 | E9: =SUM(E3:E8) -> #REF! | F9: =SUM(F3:F8) -> #REF! | G9: =SUM(G3:G8) -> #REF! | H9: =SUM(H3:H8) -> #REF! | I9: =SUM(I3:I8) -> #REF! | J9: =SUM(J3:J8) -> #REF!
B11: TEST PLAN
B13: No | C13: Function ID | D13: Function Name | E13: Platform | F13: Screen list | G13: Est viewpoint | H13: Create Test Cases | L13: Execute Test Cases
H14: Est Time (h) | I14: Act Time (h) | J14: PIC | K14: Status | L14: Round 1 Est Time(h) | M14: Round 1 Act Time (h) | N14: Round 2 Est Time(h) | O14: Round 2 Act Time (h) | P14: Total Time (h) | Q14: PIC | R14: Status
B16: =ROW()-6 -> 10 | C16: FUNC01 | D16: Tra cứu văn bản pháp luật | J16: Trang.bui3 | K16: Review | P16: =L16+N16 -> 0

Sheet Revisions
A1: HISTORY
A3: History
A4: Date | B4: Content | C4: Version | D4: Author
A5: =Overview!E19 -> 46153 | B5: Thêm mới | C5: 0.1 | D5: =Overview!E17 -> Trang.bui3

Sheet Tra cứu văn bản pháp luật
A1: System Name | B1: Cổng Một Cửa Đầu Tư Quốc Gia - Ứng dụng Di động | D1: MBFS_UC69_TraCuuVanBanPhapLuat_Testcase_v1.0 | G1: Browser | H1: iOS | I1: Pass | J1: =COUNTIF(G8:G291,"Pass") -> 0 | K1: Android | L1: Pass | M1: =COUNTIF(K8:K291,"Pass") -> 0 | N1: Number of Test cases | O1: =SUM(J1:J4)+SUM(M1:M4) -> 254 | P1: Number of Bugs | Q1: =COUNTA(#REF!)+COUNTA(#REF!) -> 2
A2: Module | B2: Ứng dụng Di động (Mobile App) | I2: Fail | J2: =COUNTIF(G8:G291,"Fail") -> 0 | L2: Fail | M2: =COUNTIF(K9:K292,"Fail") -> 0
A3: Function Name | D3: Tra cứu văn bản pháp luật | I3: Untested | J3: =COUNTIF(G10:G293,"Untested") -> 127 | L3: Untested | M3: =COUNTIF(K10:K293,"Untested") -> 127
A4: Created By | B4: =Overview!E17 -> Trang.bui3 | D4: 11/05/2026 | I4: N/A | J4: =COUNTIF(G8:G291,"N/A") -> 0 | L4: N/A | M4: =COUNTIF(K11:K294,"N/A") -> 0
A5: Execute By | I5: Pending | J5: =COUNTIF(G8:G291,"Pending") -> 0 | L5: Pending | M5: =COUNTIF(K12:K295,"Pending") -> 0
A6: ID_TC | B6: Test Title/Summary of test cases | C6: Pre-Condition | D6: Step | E6: Expected Result | F6: Data/Note | G6: Round 1 - iOS | K6: Round 1 - Android | O6: Round 2 - iOS | Q6: Round 2 - Android
G7: Test Result | H7: PIC | I7: Execute Date | J7: ID Bug | K7: Test Result | L7: PIC | M7: Execute Date | N7: ID Bug | O7: Test Result | P7: PIC | Q7: Test Result | R7: PIC
B8: 1. Màn hình Danh sách Văn bản pháp luật
B9: Check UI/UX
A10: ="TC_" & TEXT(ROW()-9,"000") -> TC_001 | B10: Kiểm tra UI/UX màn hình Danh sách Văn bản pháp luật | C10: Đăng nhập thành công vào ứng dụng (Cá nhân hoặc Tổ chức). Điều hướng đến màn hình "Văn bản pháp luật". | D10: 1. Kiểm tra hiển thị trên màn hình [Danh sách Văn bản pháp luật] | E10: 1. Hiển thị đầy đủ các item, màu sắc, font chữ, layout giống Design (Tham khảo ảnh "1. Màn xem danh sách - Số hiệu, trích yếu" sheet WF/Design) - Header đỏ đậm, tiêu đề "Văn bản pháp luật" màu trắng, nút Quay lại (←) - Ô tìm kiếm nền xám nhạt, viền bo tròn, placeholder "Tìm kiếm văn bản..." - Icon filter bên phải ô tìm kiếm - 2 radio: "Số hiệu, Trích yếu" (mặc định) và "Toàn văn" - Danh sách Card cuộn dọc | G10: Untested | K10: Untested
A11: ="TC_" & TEXT(ROW()-9,"000") -> TC_002 | B11: [Card văn bản] Kiểm tra hiển thị thông tin trên mỗi Card | C11: Đăng nhập thành công. Ở màn hình Danh sách Văn bản pháp luật. Danh sách có dữ liệu. | D11: 1. Kiểm tra hiển thị thông tin trên 1 Card văn bản | E11: 1. - Tag Loại văn bản: góc trái trên - Tag Trạng thái: góc phải trên - Tên văn bản: font đậm, màu đen, tối đa 2 dòng - "Ban hành: [DD/MM/YYYY]" dòng 1, màu xám - "Hiệu lực: [DD/MM/YYYY]" dòng 2, màu xám - Cơ quan ban hành: góc trái dưới, màu xám đậm - Nút "Xem chi tiết →": góc phải dưới | G11: Untested | K11: Untested
A12: ="TC_" & TEXT(ROW()-9,"000") -> TC_003 | B12: [Card văn bản] Kiểm tra hiển thị khi Tên văn bản quá dài (> 2 dòng) | C12: Đăng nhập thành công. Có văn bản với tên rất dài (> 2 dòng hiển thị). | D12: 1. Kiểm tra hiển thị Tên văn bản trên Card | E12: 1. Tên văn bản hiển thị tối đa 2 dòng, phần vượt quá hiển thị "..." | G12: Untested | K12: Untested
A13: ="TC_" & TEXT(ROW()-9,"000") -> TC_004 | B13: [Card văn bản] Kiểm tra hiển thị khi các trường dữ liệu null | C13: Đăng nhập thành công. Có văn bản với các trường null. | D13: 1. Kiểm tra hiển thị Card khi dữ liệu null | E13: 1. - Tên văn bản null → hiển thị "-" - Ngày ban hành null → "Ban hành: -" - Ngày hiệu lực null → "Hiệu lực: -" - Cơ quan ban hành null → "-" | G13: Untested | K13: Untested
A14: ="TC_" & TEXT(ROW()-9,"000") -> TC_005 | B14: [Tag Trạng thái] Kiểm tra hiển thị badge cho 5 trạng thái | C14: Đăng nhập thành công. Ở màn hình Danh sách Văn bản pháp luật. Danh sách có dữ liệu. | D14: 1. Kiểm tra hiển thị badge trạng thái trên các Card | E14: 1. Badge hiển thị đúng cho 5 giá trị: - "Đang hiệu lực" - "Chưa hiệu lực" - "Không xác định hiệu lực" - "Hết hiệu lực" - "Hết hiệu lực một phần" Badge luôn read-only, không cho phép tap (CMR-05) | G14: Untested | K14: Untested
A15: ="TC_" & TEXT(ROW()-9,"000") -> TC_006 | B15: [Full-screen loading] Kiểm tra hiển thị loading khi first-load | C15: Đăng nhập thành công. Truy cập lần đầu vào màn hình "Văn bản pháp luật". | D15: 1. Kiểm tra hiển thị trong lúc tải dữ liệu lần đầu | E15: 1. Hiển thị full-screen loading overlay (CMR-07 v1.1) trong lúc chờ API phản hồi | G15: Untested | K15: Untested
A16: ="TC_" & TEXT(ROW()-9,"000") -> TC_007 | B16: [Empty state] Kiểm tra hiển thị khi không có dữ liệu | C16: Đăng nhập thành công. API trả về danh sách rỗng. | D16: 1. Kiểm tra hiển thị màn hình khi không có văn bản nào | E16: 1. Hiển thị empty state "Không tìm thấy kết quả." theo CMR-14. Ẩn danh sách kết quả. | G16: Untested | K16: Untested
A17: ="TC_" & TEXT(ROW()-9,"000") -> TC_008 | B17: [Active Filter Indicator] Kiểm tra hiển thị icon indicator khi có filter active | C17: Đăng nhập thành công. Đã áp dụng bộ lọc có giá trị khác mặc định. | D17: 1. Kiểm tra hiển thị icon filter trên màn hình danh sách | E17: 1. Icon indicator màu xanh lá cây xuất hiện ở góc phải trên icon filter (CMR-02) | G17: Untested | K17: Untested
A18: ="TC_" & TEXT(ROW()-9,"000") -> TC_009 | B18: [Active Filter Indicator] Kiểm tra ẩn icon indicator khi không có filter active | C18: Đăng nhập thành công. Tất cả field bộ lọc ở giá trị mặc định. | D18: 1. Kiểm tra hiển thị icon filter trên màn hình danh sách | E18: 1. Không hiển thị icon indicator. Chỉ hiển thị icon filter bình thường. | G18: Untested | K18: Untested
B19: Check Function
A20: ="TC_" & TEXT(ROW()-10,"000") -> TC_010 | B20: [Ô tìm kiếm] Kiểm tra tìm kiếm với phạm vi "Số hiệu, Trích yếu" | C20: Đăng nhập thành công. Ở màn hình Danh sách Văn bản pháp luật. Danh sách có dữ liệu. | D20: 1. Nhập từ khóa "Thông tư" vào ô tìm kiếm 2. Chờ 3 giây (debounce) 3. Kiểm tra hiển thị danh sách kết quả | E20: 3. Danh sách cập nhật, chỉ hiển thị các văn bản có tên/số hiệu/trích yếu chứa "Thông tư" | G20: Untested | K20: Untested
A21: ="TC_" & TEXT(ROW()-10,"000") -> TC_011 | B21: [Ô tìm kiếm] Kiểm tra tìm kiếm với phạm vi "Toàn văn" | C21: Đăng nhập thành công. Ở màn hình Danh sách Văn bản pháp luật, mục Toàn văn Danh sách có dữ liệu. | D21: 1. Nhập từ khóa "Thông tư" vào ô tìm kiếm 2. Chờ 3 giây (debounce) 3. Kiểm tra hiển thị danh sách kết quả | E21: 3. Danh sách cập nhật, chỉ hiển thị các văn bản có toàn văn chứa "Thông tư" | G21: Untested | K21: Untested
A22: ="TC_" & TEXT(ROW()-10,"000") -> TC_012 | B22: [Ô tìm kiếm] Kiểm tra debounce 3 giây hoạt động đúng | C22: Đăng nhập thành công. Ở màn hình Danh sách Văn bản pháp luật. Danh sách có dữ liệu. | D22: 1. Nhập "Nghị" vào ô tìm kiếm 2. Chờ 1 giây, nhập thêm " định" 3. Chờ 3 giây không gõ thêm 4. Kiểm tra hiển thị | E22: 4. Hệ thống chỉ gọi API 1 lần sau 3 giây ngừng gõ, kết quả cho "Nghị định" | F22: CMR-01 | G22: Untested | K22: Untested
A23: ="TC_" & TEXT(ROW()-10,"000") -> TC_013 | B23: [Ô tìm kiếm] Kiểm tra tìm kiếm gần đúng (fuzzy search) | C23: Đăng nhập thành công. Ở màn hình Danh sách Văn bản pháp luật. Danh sách có dữ liệu. | D23: 1. Nhập "20/2026" vào ô tìm kiếm 2. Chờ 3 giây 3. Kiểm tra kết quả | E23: 3. Kết quả trả về bao gồm văn bản chứa "20/2026" (tìm gần đúng) | G23: Untested | K23: Untested
A24: ="TC_" & TEXT(ROW()-10,"000") -> TC_014 | B24: [Ô tìm kiếm] Kiểm tra giới hạn 500 ký tự — nhập đúng 500 (BVA) | C24: Đăng nhập thành công. Ở màn hình Danh sách Văn bản pháp luật. Danh sách có dữ liệu. | D24: 1. Nhập đúng 500 ký tự vào ô tìm kiếm 2. Chờ 3 giây 3. Kiểm tra hiển thị | E24: 2. Hệ thống chấp nhận 500 ký tự 3. Thực hiện tìm kiếm bình thường | F24: BVA: at boundary | G24: Untested | K24: Untested
A25: ="TC_" & TEXT(ROW()-10,"000") -> TC_015 | B25: [Ô tìm kiếm] Kiểm tra giới hạn 500 ký tự — nhập 501 (BVA) | C25: Đăng nhập thành công. Ở màn hình Danh sách Văn bản pháp luật. Danh sách có dữ liệu. | D25: 1. Nhập 501 ký tự vào ô tìm kiếm | E25: 1. Hệ thống không cho phép nhập ký tự thứ 501. Chặn tại 500 ký tự. | F25: BVA: above boundary | G25: Untested | K25: Untested
A26: ="TC_" & TEXT(ROW()-10,"000") -> TC_016 | B26: [Ô tìm kiếm] Kiểm tra xóa hết từ khóa → danh sách mặc định | C26: Đăng nhập thành công. Đã nhập từ khóa và có kết quả tìm kiếm. | D26: 1. Xóa hết text trong ô tìm kiếm 2. Chờ 3 giây 3. Kiểm tra hiển thị | E26: 3. Hiển thị lại danh sách mặc định (sắp xếp theo ngày ban hành mới nhất) | G26: Untested | K26: Untested
A27: ="TC_" & TEXT(ROW()-10,"000") -> TC_017 | B27: [Ô tìm kiếm] Kiểm tra nhập ký tự đặc biệt | C27: Đăng nhập thành công. Ở màn hình Danh sách Văn bản pháp luật. Danh sách có dữ liệu. | D27: 1. Nhập "@#/-.%" vào ô tìm kiếm 2. Chờ 3 giây 3. Kiểm tra hiển thị | E27: 3. Hệ thống xử lý bình thường, không crash. Trả về kết quả phù hợp hoặc empty state. | G27: Untested | K27: Untested
A28: ="TC_" & TEXT(ROW()-10,"000") -> TC_018 | B28: [Radio] Kiểm tra chuyển từ "Số hiệu, Trích yếu" sang "Toàn văn" | C28: Đăng nhập thành công. Đã nhập keyword "Thông tư". Bộ lọc đã áp dụng. | D28: 1. Tap radio "Toàn văn" 2. Kiểm tra hiển thị | E28: 2. - Danh sách reset về trang đầu - Keyword giữ nguyên - Bộ lọc giữ nguyên - Mỗi Card hiển thị thêm khối nội dung toàn văn | G28: Untested | K28: Untested
A29: ="TC_" & TEXT(ROW()-10,"000") -> TC_019 | B29: [Radio] Kiểm tra chuyển từ "Toàn văn" về "Số hiệu, Trích yếu" | C29: Đăng nhập thành công. Radio "Toàn văn" đang chọn. Có keyword và bộ lọc. | D29: 1. Tap radio "Số hiệu, Trích yếu" 2. Kiểm tra hiển thị | E29: 2. - Danh sách reset về trang đầu - Keyword giữ nguyên, bộ lọc giữ nguyên - Khối nội dung toàn văn ẩn đi | G29: Untested | K29: Untested
A30: ="TC_" & TEXT(ROW()-10,"000") -> TC_020 | B30: [Radio "Toàn văn"] Kiểm tra khi VB không có nội dung toàn văn | C30: Đăng nhập thành công. Radio "Toàn văn" đang chọn. | D30: 1. Kiểm tra hiển thị khối toàn văn trên Card không có data | E30: 1. Khối toàn văn hiển thị "Không có dữ liệu." theo CMR-14 | G30: Untested | K30: Untested
A31: ="TC_" & TEXT(ROW()-10,"000") -> TC_021 | B31: [Lazy load] Kiểm tra tải thêm 20 bản ghi khi cuộn xuống | C31: Đăng nhập thành công. Danh sách có > 20 bản ghi. | D31: 1. Cuộn xuống cuối danh sách 2. Kiểm tra hiển thị | E31: 1. Hiển thị spinner cục bộ ở cuối (không full-screen) 2. Tải thêm 20 bản ghi tiếp theo | F31: CMR-04 | G31: Untested | K31: Untested
A32: ="TC_" & TEXT(ROW()-10,"000") -> TC_022 | B32: [Lazy load] Kiểm tra khi đã tải hết dữ liệu | C32: Đăng nhập thành công. Đã tải hết tất cả bản ghi. | D32: 1. Cuộn xuống cuối danh sách 2. Kiểm tra hiển thị | E32: 2. Không trigger thêm API call, không hiển thị spinner. | G32: Untested | K32: Untested
A33: ="TC_" & TEXT(ROW()-10,"000") -> TC_023 | B33: [Pull to Refresh] Kiểm tra kéo xuống để tải lại | C33: Đăng nhập thành công. Có keyword và bộ lọc đang active. | D33: 1. Kéo xuống (pull to refresh) 2. Kiểm tra hiển thị | E33: 2. Danh sách tải lại từ đầu, giữ nguyên keyword và bộ lọc | F33: CMR-13 | G33: Untested | K33: Untested
A34: ="TC_" & TEXT(ROW()-10,"000") -> TC_024 | B34: [Nút "Xem chi tiết →"] Kiểm tra tap mở chi tiết | C34: Đăng nhập thành công. Ở màn hình Danh sách Văn bản pháp luật. Danh sách có dữ liệu. | D34: 1. Tap nút "Xem chi tiết →" trên 1 Card 2. Kiểm tra hiển thị | E34: 2. Chuyển đến màn hình Chi tiết văn bản tương ứng | G34: Untested | K34: Untested
A35: ="TC_" & TEXT(ROW()-10,"000") -> TC_025 | B35: [Card văn bản] Kiểm tra tap toàn bộ Card mở chi tiết | C35: Đăng nhập thành công. Ở màn hình Danh sách Văn bản pháp luật. Danh sách có dữ liệu. | D35: 1. Tap vào vùng bất kỳ trên Card 2. Kiểm tra hiển thị | E35: 2. Chuyển đến màn hình Chi tiết văn bản tương ứng | G35: Untested | K35: Untested
A36: ="TC_" & TEXT(ROW()-10,"000") -> TC_026 | B36: [Debounce rapid tap] Kiểm tra tap nhanh liên tiếp chỉ navigate 1 lần | C36: Đăng nhập thành công. Ở màn hình Danh sách Văn bản pháp luật. Danh sách có dữ liệu. | D36: 1. Tap nhanh liên tiếp 3 lần vào 1 Card 2. Kiểm tra hiển thị | E36: 2. Chỉ navigate 1 lần đến Chi tiết (CMR-18) | F36: CMR-18 | G36: Untested | K36: Untested
A37: ="TC_" & TEXT(ROW()-10,"000") -> TC_027 | B37: [Nút Quay lại] Kiểm tra quay về màn hình trước | C37: Đăng nhập thành công. Ở màn hình Danh sách. Truy cập từ Trang chủ. | D37: 1. Tap nút Quay lại (←) trên header 2. Kiểm tra hiển thị | E37: 2. Quay về Trang chủ (CMR-06) | G37: Untested | K37: Untested
A38: ="TC_" & TEXT(ROW()-10,"000") -> TC_028 | B38: [State Persistence] Kiểm tra quay lại giữ nguyên trạng thái | C38: Đăng nhập thành công. Đã nhập keyword, áp dụng bộ lọc, cuộn xuống giữa danh sách. | D38: 1. Tap vào 1 Card để xem chi tiết 2. Tap Quay lại để về danh sách 3. Kiểm tra hiển thị | E38: 3. - Keyword giữ nguyên - Bộ lọc giữ nguyên - Vị trí scroll giữ nguyên - Radio giữ nguyên | F38: CMR-01 | G38: Untested | K38: Untested
A39: ="TC_" & TEXT(ROW()-10,"000") -> TC_029 | B39: [Tìm kiếm + Bộ lọc] Kiểm tra kết hợp keyword và bộ lọc | C39: Đăng nhập thành công. Ở màn hình Danh sách Văn bản pháp luật. Danh sách có dữ liệu. | D39: 1. Nhập "Thông tư" vào ô tìm kiếm 2. Mở bộ lọc, chọn Trạng thái = "Đang hiệu lực" 3. Tap "Áp dụng" 4. Chờ 3 giây 5. Kiểm tra kết quả | E39: 5. Danh sách chỉ hiển thị VB chứa "Thông tư" VÀ trạng thái "Đang hiệu lực" (AND logic) | G39: Untested | K39: Untested
A40: ="TC_" & TEXT(ROW()-10,"000") -> TC_030 | B40: [Lỗi mạng] Kiểm tra mất kết nối khi tải danh sách | C40: Đăng nhập thành công. Tắt mạng trước khi truy cập UC69. | D40: 1. Truy cập màn hình "Văn bản pháp luật" 2. Kiểm tra hiển thị | E40: 2. Hiển thị "Không thể kết nối. Vui lòng kiểm tra mạng và thử lại." với nút "Thử lại" | F40: CMR-07 | G40: Untested | K40: Untested
...

Sheet Master Plan
C3: MASTER PLAN - Update Địa Chỉ Hành Chính mới 0609
B5: No | C5: Platform | D5: Screen list | E5: Testcase/Checklist | I5: Execute test + test report | N5: Note
E6: PIC | F6: Start date | G6: End date | H6: Status | I6: PIC | J6: Start date | K6: End date | L6: Days | M6: Status
B7: 1 | C7: Web- Admin | D7: Đăng ký | E7: Thảo | I7: Thảo + Hằng + Trang | J7: 45915 | K7: 45922 | L7: 4
D8: Chỉnh sửa | E8: Thảo | I8: Thảo + Hằng + Trang | J8: 45915 | K8: 45922
D9: [Quản lý danh mục] Tỉnh/Thành phố | E9: Thảo | I9: Thảo + Hằng + Trang | J9: 45915 | K9: 45922
D10: [Quản lý danh mục] Xã/phường | E10: Thảo | I10: Thảo + Hằng + Trang | J10: 45915 | K10: 45922
D11: [Quản lý đơn hàng] Chỉnh sửa địa chỉ ship tem | E11: Thảo | I11: Thảo + Hằng + Trang | J11: 45915 | K11: 45922
D12: [Yêu cầu phát hành lại thẻ] Tạo y/c PHL thẻ | E12: Thảo | I12: Thảo + Hằng + Trang | J12: 45915 | K12: 45922
B13: 2 | D13: [BC vé tháng] T15. Danh sách thẻ chuyển phát nhanh | E13: Thảo | I13: Thảo + Hằng + Trang | J13: 45915 | K13: 45922
D14: Impact các Báo cáo cũ có hiển thị thông tin địa chỉ | I14: Thảo + Hằng + Trang | J14: 45915 | K14: 45922
B15: 3 | C15: Web- Online | D15: Đăng ký | E15: Thảo | I15: Thảo + Hằng + Trang | J15: 45915 | K15: 45922 | L15: 3
B16: 4 | D16: Chỉnh sửa | E16: Thảo | I16: Thảo + Hằng + Trang | J16: 45915 | K16: 45922
B17: 5 | D17: Gia hạn vé tháng | E17: Thảo | I17: Thảo + Hằng + Trang | J17: 45915 | K17: 45922
B18: 6 | D18: Phát hành lại thẻ | E18: Thảo | I18: Thảo + Hằng + Trang | J18: 45915 | K18: 45922
B19: 7 | C19: Web- Đại lý | D19: (null)
B20: 22 | C20: App khách hàng | D20: Đăng ký | E20: Hằng | I20: Trang+ Hằng | J20: 45908 | K20: 45912 | L20: 5 | M20: Done
D21: Chỉnh sửa đơn đăng ký | E21: Hằng | I21: Trang+ Hằng | J21: 45908 | K21: 45912 | M21: Done
B22: 24 | D22: Gia hạn vé tháng | E22: Hằng | I22: Trang+ Hằng | J22: 45908 | K22: 45912 | M22: Done
D23: Mã QR thẻ | E23: Hằng | I23: Trang+ Hằng | J23: 45908 | K23: 45912 | M23: Done
D24: Nạp điểm (theo chính sách giá vé mới) | E24: Hằng | I24: Trang+ Hằng | J24: 45908 | K24: 45912 | M24: Done
D25: Vé lượt | E25: Hằng | I25: Trang+ Hằng | J25: 45908 | K25: 45912 | M25: Done
B26: 28 | D26: Tra cứu buýt | E26: Hằng | I26: Trang+ Hằng | J26: 45908 | K26: 45912 | M26: Done
B27: 29 | C27: App In Thẻ | E27: Trang | L27: 1 | M27: Doing

Sheet WFDesign
A1: 1. Màn xem danh sách - Số hiệu, trích yếu | D1: 2. Màn xem danh sách - Toàn văn | F1: 3. Màn xem chi tiết | G1: 4. Bộ lọc | I1: 5. Mục lục văn bản
H39: h
